2023-11-29 21:30:17,423 - instabot version: 0.117.0 (bot) - INFO - Instabot version: 0.117.0 Started
2023-11-29 21:30:17,424 - instabot version: 0.117.0 (bot) - DEBUG - Bot imported from C:\Users\user\AppData\Local\Programs\Python\Python311\Lib\site-packages\instabot\bot\bot.py
2023-11-29 21:30:17,425 - instabot version: 0.117.0 (api_login) - INFO - Not yet logged in starting: PRE-LOGIN FLOW!
2023-11-29 21:30:18,237 - instabot version: 0.117.0 (api) - DEBUG - POST to endpoint: accounts/get_prefill_candidates/ returned response: <Response [429]>
2023-11-29 21:30:18,238 - instabot version: 0.117.0 (api) - DEBUG - Responsecode indicates error; response content: b'{"message":"Please wait a few minutes before you try again.","status":"fail"}'
2023-11-29 21:30:18,239 - instabot version: 0.117.0 (api) - ERROR - Request returns 429 error!
2023-11-29 21:30:18,240 - instabot version: 0.117.0 (api) - WARNING - That means 'too many requests'. I'll go to sleep for 5 minutes.
2023-11-29 21:35:18,241 - instabot version: 0.117.0 (api) - WARNING - HTTPSConnectionPool(host='i.instagram.com', port=443): Max retries exceeded with url: /api/v1/accounts/get_prefill_candidates/ (Caused by NewConnectionError('<urllib3.connection.HTTPSConnection object at 0x000001A6770B1910>: Failed to establish a new connection: [Errno 11001] getaddrinfo failed'))
2023-11-29 21:35:18,256 - instabot version: 0.117.0 (api) - WARNING - HTTPSConnectionPool(host='i.instagram.com', port=443): Max retries exceeded with url: /api/v1/qe/sync/ (Caused by NewConnectionError('<urllib3.connection.HTTPSConnection object at 0x000001A6770B8F50>: Failed to establish a new connection: [Errno 11001] getaddrinfo failed'))
2023-11-29 21:35:18,264 - instabot version: 0.117.0 (api) - WARNING - HTTPSConnectionPool(host='i.instagram.com', port=443): Max retries exceeded with url: /api/v1/launcher/sync/ (Caused by NewConnectionError('<urllib3.connection.HTTPSConnection object at 0x000001A6770B9A50>: Failed to establish a new connection: [Errno 11001] getaddrinfo failed'))
2023-11-29 21:35:18,268 - instabot version: 0.117.0 (api) - WARNING - HTTPSConnectionPool(host='i.instagram.com', port=443): Max retries exceeded with url: /api/v1/accounts/contact_point_prefill/ (Caused by NewConnectionError('<urllib3.connection.HTTPSConnection object at 0x000001A6770BA150>: Failed to establish a new connection: [Errno 11001] getaddrinfo failed'))
