2023-11-29 21:36:33,769 - instabot version: 0.117.0 (bot) - INFO - Instabot version: 0.117.0 Started
2023-11-29 21:36:33,769 - instabot version: 0.117.0 (bot) - DEBUG - Bot imported from C:\Users\user\AppData\Local\Programs\Python\Python311\Lib\site-packages\instabot\bot\bot.py
2023-11-29 21:36:33,769 - instabot version: 0.117.0 (api_login) - INFO - Not yet logged in starting: PRE-LOGIN FLOW!
2023-11-29 21:36:33,769 - instabot version: 0.117.0 (api) - WARNING - HTTPSConnectionPool(host='i.instagram.com', port=443): Max retries exceeded with url: /api/v1/accounts/get_prefill_candidates/ (Caused by NewConnectionError('<urllib3.connection.HTTPSConnection object at 0x000002A736BF1910>: Failed to establish a new connection: [Errno 11001] getaddrinfo failed'))
2023-11-29 21:36:33,786 - instabot version: 0.117.0 (api) - WARNING - HTTPSConnectionPool(host='i.instagram.com', port=443): Max retries exceeded with url: /api/v1/qe/sync/ (Caused by NewConnectionError('<urllib3.connection.HTTPSConnection object at 0x000002A736BF2390>: Failed to establish a new connection: [Errno 11001] getaddrinfo failed'))
2023-11-29 21:36:33,788 - instabot version: 0.117.0 (api) - WARNING - HTTPSConnectionPool(host='i.instagram.com', port=443): Max retries exceeded with url: /api/v1/launcher/sync/ (Caused by NewConnectionError('<urllib3.connection.HTTPSConnection object at 0x000002A736BF2A10>: Failed to establish a new connection: [Errno 11001] getaddrinfo failed'))
2023-11-29 21:36:33,790 - instabot version: 0.117.0 (api) - WARNING - HTTPSConnectionPool(host='i.instagram.com', port=443): Max retries exceeded with url: /api/v1/accounts/contact_point_prefill/ (Caused by NewConnectionError('<urllib3.connection.HTTPSConnection object at 0x000002A736BF3090>: Failed to establish a new connection: [Errno 11001] getaddrinfo failed'))
