2023-11-29 21:37:16,686 - instabot version: 0.117.0 (bot) - INFO - Instabot version: 0.117.0 Started
2023-11-29 21:37:16,686 - instabot version: 0.117.0 (bot) - DEBUG - Bot imported from C:\Users\user\AppData\Local\Programs\Python\Python311\Lib\site-packages\instabot\bot\bot.py
2023-11-29 21:37:16,686 - instabot version: 0.117.0 (api_login) - INFO - Not yet logged in starting: PRE-LOGIN FLOW!
2023-11-29 21:37:16,686 - instabot version: 0.117.0 (api) - WARNING - HTTPSConnectionPool(host='i.instagram.com', port=443): Max retries exceeded with url: /api/v1/accounts/get_prefill_candidates/ (Caused by NewConnectionError('<urllib3.connection.HTTPSConnection object at 0x000001E057031910>: Failed to establish a new connection: [Errno 11001] getaddrinfo failed'))
2023-11-29 21:37:16,704 - instabot version: 0.117.0 (api) - WARNING - HTTPSConnectionPool(host='i.instagram.com', port=443): Max retries exceeded with url: /api/v1/qe/sync/ (Caused by NewConnectionError('<urllib3.connection.HTTPSConnection object at 0x000001E057032390>: Failed to establish a new connection: [Errno 11001] getaddrinfo failed'))
2023-11-29 21:37:16,706 - instabot version: 0.117.0 (api) - WARNING - HTTPSConnectionPool(host='i.instagram.com', port=443): Max retries exceeded with url: /api/v1/launcher/sync/ (Caused by NewConnectionError('<urllib3.connection.HTTPSConnection object at 0x000001E057032A10>: Failed to establish a new connection: [Errno 11001] getaddrinfo failed'))
2023-11-29 21:37:16,709 - instabot version: 0.117.0 (api) - WARNING - HTTPSConnectionPool(host='i.instagram.com', port=443): Max retries exceeded with url: /api/v1/accounts/contact_point_prefill/ (Caused by NewConnectionError('<urllib3.connection.HTTPSConnection object at 0x000001E057033090>: Failed to establish a new connection: [Errno 11001] getaddrinfo failed'))
